Workbook

Sheet dataset- CAIF corriente
A2: Presupuesto (millones de pesos) del Gobierno de la Ciudad de Buenos Aires . Esquema de Ahorro - Inversión - Financiamiento. Consolidado general. Años 1995/2025 | AG2: Proyecto 2027 (Planilla 16)
A3: Concepto | B3: 1995 | C3: 1996 | D3: 1997 | E3: 1998 | F3: 1999 | G3: 2000 | H3: 2001 | I3: 2002 | J3: 2003 | K3: 2004 | L3: 2005 | M3: 2006 | N3: 2007 | O3: 2008 | P3: 2009 | Q3: 2010 | R3: 2011 | S3: 2012 | T3: 2013 | U3: 2014 | V3: 2015 | W3: 2016 | X3: 2017 | Y3: 2018 | Z3: 2019 | AA3: 2020 | AB3: 2021 | AC3: 2022 | AD3: 2023 | AE3: 2024 | AF3: 2025* | AG3: 2027P
A4: 1) Ingresos corrientes | B4: 2667.35 | C4: 2719.4 | D4: 2810.7719 | E4: 3124.19 | F4: 3195.19 | G4: 3219.08 | H4: 2927.3387 | I4: 2879.9705 | J4: 3992.3622 | K4: 5138.6651 | L4: 6096.0067 | M4: 7532.5194 | N4: 9531.7452 | O4: 12702.573 | P4: 14915.992 | Q4: 19416.34 | R4: 25765.35 | S4: 33304.302 | T4: 47348.934 | U4: 63713.466 | V4: 80949.768 | W4: 128692.46 | X4: 180282.05 | Y4: 269134.19 | Z4: 350978.54 | AA4: 435154.2 | AB4: 677074 | AC4: 1306253.9 | AD4: 3300184.4 | AE4: 9426456.8 | AF4: 13454248 | AG4: 24092481
A5: Ingresos tributarios | B5: 2462.23 | C5: 2490.1 | D5: 2550.6721 | E5: 2700.52 | F5: 2926.07 | G5: 2898.31 | H5: 2650.5381 | I5: 2609.6163 | J5: 3604.6318 | K5: 4190.7531 | L5: 5000.8549 | M5: 6958.805 | N5: 8850.5992 | O5: 11964.591 | P5: 14005.768 | Q5: 18289.93 | R5: 24194.547 | S5: 31205.03 | T5: 44688.216 | U5: 60199.236 | V5: 76854.743 | W5: 121588.68 | X5: 166817.75 | Y5: 231751.85 | Z5: 319988.03 | AA5: 412373.6 | AB5: 607641.73 | AC5: 1160662.3 | AD5: 2950237.9 | AE5: 7845601.2 | AF5: 11258558 | AG5: 19094214
A6: Ingresos no tributarios | B6: 132.12 | C6: 138.4 | D6: 179.48496 | E6: 158.48 | F6: 171.11 | G6: 197.16 | H6: 175.58365 | I6: 183.06238 | J6: 191.16995 | K6: 225.37798 | L6: 228.61641 | M6: 300.81235 | N6: 418.48326 | O6: 482.22363 | P6: 610.66471 | Q6: 668.97 | R6: 968.03115 | S6: 1138.3862 | T6: 1810.902 | U6: 2227.442 | V6: 2749.9178 | W6: 4053.1162 | X6: 7452.1602 | Y6: 8035.6598 | Z6: 13871.565 | AA6: 8336.5 | AB6: 17993.084 | AC6: 36551.207 | AD6: 63998.228 | AE6: 2816.3956 | AF6: 331219.34 | AG6: 663825.63
A7: Venta de bienes y servicios | B7: 41.74 | C7: 54.1 | D7: 80.614837 | E7: 47.8 | F7: 38.11 | G7: 36.35 | H7: 35.234236 | I7: 29.87078 | J7: 37.973083 | K7: 38.40943 | L7: 38.912931 | M7: 42.646816 | N7: 49.846537 | O7: 54.415532 | P7: 71.498373 | Q7: 113.75 | R7: 149.42154 | S7: 212.76477 | T7: 229.79755 | U7: 396.95648 | V7: 511.42698 | W7: 679.69484 | X7: 1411.1275 | Y7: 24331.772 | Z7: 3495.2191 | AA7: 3602.6 | AB7: 6835.1298 | AC7: 14132.068 | AD7: 35425.476 | AE7: 274484.55 | AF7: 197702.42 | AG7: 365617.42
A8: Rentas de la propiedad | B8: - | C8: - | D8: - | E8: - | F8: - | G8: - | H8: 13.825274 | I8: - | J8: 14.783847 | K8: 14.290116 | L8: 41.933345 | M8: 76.536607 | N8: 21.912071 | O8: 38.083279 | P8: 10.877034 | Q8: 77.48 | R8: 108.39771 | S8: 133.91045 | T8: 140.1788 | U8: 300.45175 | V8: 117.00633 | W8: 835.68358 | X8: 410.07804 | Y8: 1363.1319 | Z8: 3799.1505 | AA8: 3601.4 | AB8: 1787.5678 | AC8: 22431.529 | AD8: 195029.37 | AE8: 723130.4 | AF8: 527668.14 | AG8: 951290.9
A9: Transferencias corrientes | B9: 31.26 | C9: 36.8 | D9: - | E9: 217.39 | F9: 59.9 | G9: 87.26 | H9: 52.157436 | I9: 57.42111 | J9: 143.80354 | K9: 669.83449 | L9: 785.68911 | M9: 153.71865 | N9: 190.90412 | O9: 163.25969 | P9: 217.18454 | Q9: 266.21 | R9: 344.95241 | S9: 614.21089 | T9: 479.83876 | U9: 589.37931 | V9: 716.67379 | W9: 1535.2917 | X9: 4190.9361 | Y9: 3651.7675 | Z9: 9824.5734 | AA9: 7240.1 | AB9: 42816.479 | AC9: 72476.748 | AD9: 55493.371 | AE9: 580424.23 | AF9: 1139100.7 | AG9: 3017533.5
A10: 2) Gastos corrientes | B10: 2440.1 | C10: 2456.6 | D10: 2603.9142 | E10: 2535.476 | F10: 2685.6359 | G10: 2823.37 | H10: 2863.5787 | I10: 2819.288 | J10: 3052.4668 | K10: 3597.3548 | L10: 4603.1244 | M10: 6491.3355 | N10: 8278.9444 | O10: 10667.733 | P10: 13338.414 | Q10: 16308.18 | R10: 22370.529 | S10: 29526.587 | T10: 40180.718 | U10: 53897.08 | V10: 74892.522 | W10: 113988.4 | X10: 150167.77 | Y10: 192822.94 | Z10: 280308.49 | AA10: 391261.5 | AB10: 563655.89 | AC10: 971054.42 | AD10: 2486215.7 | AE10: 7594736.5 | AF10: 11028860 | AG10: 19176736
A11: Remuneraciones al personal | B11: 1624.6 | C11: 1651.6 | D11: 1723.3 | E11: 1656.5775 | F11: 1733.9838 | G11: 1802.81 | H11: 1825.7179 | I11: 1776.4778 | J11: 1798.2841 | K11: 2036.2156 | L11: 2733.0001 | M11: 3941.9714 | N11: 5047.5385 | O11: 6577.0398 | P11: 8112.0139 | Q11: 9805.66 | R11: 13264.604 | S11: 17340.628 | T11: 23215.41 | U11: 30778.438 | V11: 42188.224 | W11: 69381.121 | X11: 89185.564 | Y11: 114224.98 | Z11: 162083.3 | AA11: 218745.1 | AB11: 305858.05 | AC11: 528442.5 | AD11: 1361908.5 | AE11: 4044771.8 | AF11: 5827652.9 | AG11: 9950480.7
A12: Gastos de consumo | B12: 578.12 | C12: 665.5 | D12: 641.8 | E12: 638.90453 | F12: 671.28813 | G12: 709.32 | H12: 725.35723 | I12: 717.74176 | J12: 916.12927 | K12: 1110.5441 | L12: 1232.2786 | M12: 1646.9384 | N12: 2020.3566 | O12: 2508.0563 | P12: 3226.5089 | Q12: 4147.71 | R12: 5806.2161 | S12: 7894.4037 | T12: 10430.208 | U12: 14987.607 | V12: 21584.905 | W12: 29067.985 | X12: 41735.618 | Y12: 54786.675 | Z12: 75313.368 | AA12: 110101.4 | AB12: 169684.5 | AC12: 289988.99 | AD12: 746988.45 | AE12: 2406218 | AF12: 3566209.4 | AG12: 6428377.5
A13: Otras Pérdidas | B13: - | C13: - | D13: - | E13: - | F13: - | G13: - | H13: - | I13: - | J13: - | K13: - | L13: - | M13: - | N13: - | O13: - | P13: - | Q13: - | R13: - | S13: - | T13: - | U13: - | V13: - | W13: 0.26 | X13: 2.652 | Y13: 110.8155 | Z13: 121.34964 | AA13: 53.4 | AB13: 19.592467 | AC13: 1363.3995 | AD13: 59.561962 | AE13: 861.20981 | AF13: 11.385292
A14: Impuestos directos | B14: - | C14: - | D14: - | E14: - | F14: - | G14: - | H14: - | I14: 0.49879241 | J14: 0.08225811 | K14: 0.16628335 | L14: 0.08648586 | M14: 4.270513e-08 | N14: 0.0252402 | O14: 1.248418 | P14: 0.00704088 | Q14: - | R14: - | S14: 0.29920095 | T14: - | U14: 0.02442475 | V14: 0.213474 | W14: 0.001395 | X14: 0.060172 | Y14: 12.559659 | Z14: 42.552639 | AA14: 23.6 | AB14: 1.87835 | AC14: 21.400756 | AD14: 73.512509 | AE14: 286.1739 | AF14: 304.59181
A15: Transferencias corrientes | B15: 237.38 | C15: 139.5 | D15: 238.8142 | E15: 239.99398 | F15: 280.36396 | G15: 311.24 | H15: 312.50363 | I15: 324.56962 | J15: 337.97115 | K15: 450.42886 | L15: 637.75921 | M15: 902.42576 | N15: 1211.024 | O15: 1581.3885 | P15: 1999.8837 | Q15: 2354.81 | R15: 3299.7085 | S15: 4291.256 | T15: 6535.1009 | U15: 8131.0111 | V15: 11119.179 | W15: 15539.03 | X15: 19243.874 | Y15: 23687.907 | Z15: 42747.915 | AA15: 62338 | AB15: 88091.877 | AC15: 151238.14 | AD15: 377185.74 | AE15: 1142599.4 | AF15: 1634681.2 | AG15: 2797878
A16: 3) Resultado económico (1-2) | B16: 227.25 | C16: 262.8 | D16: 206.85774 | E16: 588.71404 | F16: 509.5541 | G16: 395.71 | H16: 63.759984 | I16: 60.682549 | J16: 939.8954 | K16: 1541.3102 | L16: 1492.8823 | M16: 1041.1839 | N16: 1252.8008 | O16: 2034.8406 | P16: 1577.5789 | Q16: 3108.16 | R16: 3394.8215 | S16: 3777.7149 | T16: 7168.2153 | U16: 9816.3857 | V16: 6057.2464 | W16: 14704.066 | X16: 30114.286 | Y16: 76311.249 | Z16: 70670.051 | AA16: 43892.7 | AB16: 113418.1 | AC16: 335199.45 | AD16: 813968.64 | AE16: 1831720.3 | AF16: 2425388.9 | AG16: 4915745.3
A17: 4) Recursos de capital | B17: 1.64 | C17: 4.3 | D17: 0.6 | E17: 0.293266 | F17: 0.3 | G17: 0.263 | H17: 0.24662772 | I17: 54.477597 | J17: 12.578865 | K17: 6.8285128 | L17: 70.993167 | M17: 72.527233 | N17: 49.538388 | O17: 56.774434 | P17: 177.14895 | Q17: 573.82 | R17: 480.69564 | S17: 459.52583 | T17: 443.58588 | U17: 647.61291 | V17: 757.63224 | W17: 871.80479 | X17: 3212.9365 | Y17: 6781.3607 | Z17: 14074.504 | AA17: 6196.4 | AB17: 3838.0966 | AC17: 20201.935 | AD17: 42837.203 | AE17: 5315.1011 | AF17: 15929.111 | AG17: 3175.5982
A18: Recursos propios de capital | B18: 1.64 | C18: 4.3 | D18: 0.6 | E18: 0.293266 | F18: 0.3 | G18: 0.263 | H18: 0.24662772 | I18: 0.18928577 | J18: 0.47622225 | K18: 0.36340658 | L18: 1.6912242 | M18: 2.0559099 | N18: 0.53475274 | O18: 0.30267503 | P18: 21.310757 | Q18: 307.21 | R18: 137.22816 | S18: 39.234007 | T18: 43.772189 | U18: 95.844505 | V18: 99.471219 | W18: 171.76035 | X18: 939.78834 | Y18: 591.1478 | Z18: 8251.9932 | AA18: 5581.6 | AB18: 3513.3309 | AC18: 17101.005 | AD18: 37797.994 | AE18: 805.21501 | AF18: 9119.9404 | AG18: 0
A19: Transferencias de capital | B19: - | C19: - | D19: - | E19: - | F19: - | G19: - | H19: - | I19: 54.288311 | J19: 12.102643 | K19: - | L19: 51.493315 | M19: 51.680249 | N19: 32.63364 | O19: 56.470228 | P19: 102.30159 | Q19: 234.22 | R19: 252.09284 | S19: 219.1099 | T19: 281.33281 | U19: 408.23527 | V19: 403.53016 | W19: 535.46731 | X19: 1588.2107 | Y19: 5556.7979 | Z19: 5410.044 | AA19: 416.3 | AB19: 156.59815 | AC19: 2713.9748 | AD19: 4604.7961 | AE19: 3835.7103 | AF19: 4596.3958 | AG19: 0
A20: Disminución de la inversión financiera | B20: - | C20: - | D20: - | E20: - | F20: - | G20: - | H20: - | I20: - | J20: 0.88544744 | K20: 6.4651062 | L20: 17.808628 | M20: 18.791074 | N20: 16.369995 | O20: 0.0015310653 | P20: 53.536603 | Q20: 32.39 | R20: 91.374638 | S20: 201.18192 | T20: 118.48088 | U20: 143.53313 | V20: 254.63086 | W20: 164.57712 | X20: 684.93745 | Y20: 633.41503 | Z20: 412.46657 | AA20: 198.5 | AB20: 168.16761 | AC20: 386.95524 | AD20: 434.41285 | AE20: 674.17584 | AF20: 2212.7743 | AG20: 3175.5982
A21: 5) Gastos de capital | B21: 226.84 | C21: 269.5 | D21: 247.2372 | E21: 219.36743 | F21: 314.06 | G21: 236.554 | H21: 244.93875 | I21: 144.85461 | J21: 321.58118 | K21: 554.95011 | L21: 1075.8196 | M21: 1594.9445 | N21: 1514.6953 | O21: 2625.5964 | P21: 2409.8733 | Q21: 3240.75 | R21: 4307.1354 | S21: 5227.0625 | T21: 9939.7703 | U21: 13689.954 | V21: 12614.642 | W21: 25711.672 | X21: 40310.179 | Y21: 51249.779 | Z21: 71534.454 | AA21: 55746.4 | AB21: 89527.014 | AC21: 182395.01 | AD21: 544006.51 | AE21: 1494643.7 | AF21: 2615220.6 | AG21: 4325717.1
A22: Inversión real directa | B22: 222.49 | C22: 262.3 | D22: 143.8972 | E22: 214.63859 | F22: 301.23 | G22: 221.968 | H22: 219.20989 | I22: 137.51423 | J22: 266.80286 | K22: 385.85534 | L22: 891.4396 | M22: 1410.0157 | N22: 1437.0931 | O22: 2518.5683 | P22: 2332.0083 | Q22: 2925.69 | R22: 4148.2519 | S22: 5019.7943 | T22: 9262.6226 | U22: 12092.422 | V22: 12339.342 | W22: 25225.359 | X22: 39870.753 | Y22: 50236.475 | Z22: 70867.276 | AA22: 55118.5 | AB22: 88490.482 | AC22: 180881.35 | AD22: 539780.52 | AE22: 1485181.6 | AF22: 2591845.9 | AG22: 4317027.3
A23: Transferencias de capital | B23: 3.63 | C23: 2.5 | D23: 3.34 | E23: 4.7288472 | F23: 12.83 | G23: 14.586 | H23: 25.195365 | I23: 5.618977 | J23: 50.957616 | K23: 129.84121 | L23: 74.281951 | M23: 51.821206 | N23: 44.163399 | O23: 32.310126 | P23: 27.155856 | Q23: 45.38 | R23: 39.548867 | S23: 105.99793 | T23: 582.52964 | U23: 143.92987 | V23: 123.7729 | W23: 252.19787 | X23: 173.09353 | Y23: 230.01139 | Z23: 318.06154 | AA23: 283.8 | AB23: 756.12146 | AC23: 1205.644 | AD23: 2787.0613 | AE23: 7501.4514 | AF23: 16895.741 | AG23: 4547.5214
A24: Inversión financiera | B24: 0.72 | C24: 4.7 | D24: 100 | E24: - | F24: - | G24: - | H24: 0.5335 | I24: 1.7214 | J24: 3.8207078 | K24: 39.253565 | L24: 110.09806 | M24: 133.10761 | N24: 33.438817 | O24: 74.718037 | P24: 50.709072 | Q24: 269.68 | R24: 119.33461 | S24: 101.27027 | T24: 94.618041 | U24: 1453.602 | V24: 151.52716 | W24: 234.11571 | X24: 266.33275 | Y24: 783.29319 | Z24: 349.1168 | AA24: 344 | AB24: 280.41013 | AC24: 308.01314 | AD24: 1438.9246 | AE24: 1960.63 | AF24: 6478.957 | AG24: 4142.3459
A25: 6) Recursos totales (1+4) | B25: 2668.99 | C25: 2723.7 | D25: 2811.3719 | E25: 3124.4833 | F25: 3195.49 | G25: 3219.343 | H25: 2927.5853 | I25: 2934.4481 | J25: 4004.9411 | K25: 5145.4936 | L25: 6166.9999 | M25: 7605.0467 | N25: 9581.2836 | O25: 12759.348 | P25: 15093.141 | Q25: 19990.16 | R25: 26246.046 | S25: 33763.828 | T25: 47792.519 | U25: 64361.079 | V25: 81707.401 | W25: 129564.27 | X25: 183494.99 | Y25: 275915.55 | Z25: 365053.04 | AA25: 441350.6 | AB25: 680912.09 | AC25: 1326455.8 | AD25: 3343021.6 | AE25: 9431771.9 | AF25: 13470178 | AG25: 24095657
A26: 7) Gasto primario (2+5) | B26: 2666.94 | C26: 2726.1 | D26: 2851.1514 | E26: 2754.8434 | F26: 2999.6959 | G26: 3059.924 | H26: 3108.5175 | I26: 2964.1426 | J26: 3374.048 | K26: 4152.305 | L26: 5678.944 | M26: 8086.28 | N26: 9793.6397 | O26: 13293.329 | P26: 15748.287 | Q26: 19548.93 | R26: 26677.664 | S26: 34753.65 | T26: 50120.489 | U26: 67587.035 | V26: 87507.164 | W26: 139700.07 | X26: 190477.95 | Y26: 244072.72 | Z26: 351842.94 | AA26: 447007.8 | AB26: 653182.91 | AC26: 1153449.4 | AD26: 3030222.2 | AE26: 9089380.2 | AF26: 13644080 | AG26: 23502453
A27: 8) Resultado primario (6-7) | B27: 2.05 | C27: -2.4 | D27: -39.779459 | E27: 369.63987 | F27: 195.7941 | G27: 159.419 | H27: -180.93214 | I27: -29.694461 | J27: 630.89308 | K27: 993.18864 | L27: 488.05583 | M27: -481.23335 | N27: -212.35608 | O27: -533.98142 | P27: -655.14545 | Q27: 441.23 | R27: -431.61829 | S27: -989.82186 | T27: -2327.9691 | U27: -3225.9557 | V27: -5799.7638 | W27: -10135.802 | X27: -6982.9562 | Y27: 31842.831 | Z27: 13210.101 | AA27: -5657.2 | AB27: 27729.184 | AC27: 173006.38 | AD27: 312799.33 | AE27: 342391.7 | AF27: -173902.62 | AG27: 593203.75
A28: 9) Intereses de la deuda pública | B28: 77.97 | C28: 139.5 | D28: 126.37967 | E28: 101.42671 | F28: 114.1 | G28: 88.74 | H28: 69.401021 | I28: 58.703219 | J28: 136.0031 | K28: 126.67419 | L28: 136.74889 | M28: 176.86377 | N28: 123.95311 | O28: 134.66318 | P28: 240.6165 | Q28: 402.66 | R28: 430.64127 | S28: 478.96544 | T28: 777.88583 | U28: 1282.1358 | V28: 1950.163 | W28: 4500.7138 | X28: 6739.0506 | Y28: 14312.165 | Z28: 33037.077 | AA28: 35913.3 | AB28: 51243.011 | AC28: 57503.615 | AD28: 99127.769 | AE28: 139645.55 | AF28: 107623.06 | AG28: 591887.31
A29: 10) Gastos totales (7+9) | B29: 2744.91 | C29: 2865.6 | D29: 2977.5311 | E29: 2856.2701 | F29: 3113.7959 | G29: 3148.664 | H29: 3177.9185 | I29: 3022.8458 | J29: 3510.0511 | K29: 4278.9791 | L29: 5815.6929 | M29: 8263.1438 | N29: 9917.5928 | O29: 13427.993 | P29: 15988.903 | Q29: 19951.59 | R29: 27108.305 | S29: 35232.615 | T29: 50898.374 | U29: 68869.17 | V29: 89457.327 | W29: 144200.78 | X29: 197217 | Y29: 258384.88 | Z29: 384880.02 | AA29: 482921.2 | AB29: 704425.92 | AC29: 1210953 | AD29: 3129350 | AE29: 9229025.7 | AF29: 13751703 | AG29: 24094341
A30: 11) Resultado financiero antes de figurativas (6-10) | B30: -75.92 | C30: -141.9 | D30: -166.15913 | E30: 268.21316 | F30: 81.694098 | G30: 70.679 | H30: -250.33316 | I30: -88.39768 | J30: 494.88998 | K30: 866.51445 | L30: 351.30694 | M30: -658.09712 | N30: -336.30919 | O30: -668.6446 | P30: -895.76194 | Q30: 38.57 | R30: -862.25956 | S30: -1468.7873 | T30: -3105.855 | U30: -4508.0915 | V30: -7749.9268 | W30: -14636.516 | X30: -13722.007 | Y30: 17530.666 | Z30: -19826.976 | AA30: -41570.6 | AB30: -23513.826 | AC30: 115502.77 | AD30: 213671.57 | AE30: 202746.15 | AF30: -281525.68 | AG30: 1316.4429
A31: 12) Contribuciones figurativas | B31: - | C31: - | D31: - | E31: - | F31: - | G31: - | H31: - | I31: - | J31: - | K31: - | L31: - | M31: 461.11277 | N31: 520.64898 | O31: 744.14654 | P31: 942.31143 | Q31: 1262.4551 | R31: 1787.5959 | S31: 2290.0419 | T31: 3708.6079 | U31: 5091.7791 | V31: 6005.3321 | W31: 11079.322 | X31: 14841.406 | Y31: 19360.984 | Z31: 24732.031 | AA31: 28640.68 | AB31: 48989.463 | AC31: 106723.75 | AD31: 298163.36 | AE31: 790952.36 | AF31: -
A32: 13) Gastos figurativos | B32: - | C32: - | D32: - | E32: - | F32: - | G32: - | H32: - | I32: - | J32: - | K32: - | L32: - | M32: 461.11277 | N32: 520.64898 | O32: 744.14654 | P32: 942.31143 | Q32: 1262.4551 | R32: 1787.5959 | S32: 2290.0419 | T32: 3708.6079 | U32: 5091.7791 | V32: 6005.3321 | W32: 11079.322 | X32: 14841.406 | Y32: 19360.984 | Z32: 24732.031 | AA32: 28640.68 | AB32: 48989.463 | AC32: 106723.75 | AD32: 298163.36 | AE32: 790952.36 | AF32: -
A33: 14) Resultado financiero (11+12-13) | B33: -75.92 | C33: -141.9 | D33: -166.15913 | E33: 268.21316 | F33: 81.694098 | G33: 70.679 | H33: -250.33316 | I33: -88.39768 | J33: 494.88998 | K33: 866.51445 | L33: 351.30694 | M33: -658.09712 | N33: -336.30919 | O33: -668.6446 | P33: -895.76194 | Q33: 38.57 | R33: -862.25956 | S33: -1468.7873 | T33: -3105.855 | U33: -4508.0915 | V33: -7749.9268 | W33: -14636.516 | X33: -13722.007 | Y33: 17530.666 | Z33: -19826.976 | AA33: -41769.103 | AB33: -23513.826 | AC33: 115502.77 | AD33: 213671.57 | AE33: 202746.15 | AF33: -281525.68
A34: 15) Fuentes financieras | B34: 643.52 | C34: 983.9 | D34: 1071.2643 | E34: - | F34: 106.2 | G34: - | H34: 613.3 | I34: 695.3 | J34: 342.66043 | K34: 507.22794 | L34: 995.35819 | M34: 1984.3462 | N34: 2190.5657 | O34: 2492.0312 | P34: 1278.9 | Q34: 2440.82 | R34: 1754.6045 | S34: 3354.5384 | T34: 2771.6053 | U34: 14573.901 | V34: 22108.829 | W34: 22197.135 | X34: 33068.209 | Y34: 21764.622 | Z34: 46687.056 | AA34: 53822.4 | AB34: 49950.385 | AC34: 32729.333 | AD34: 33035.616 | AE34: 1124332.7 | AF34: 937134.32
A35: Disminución de la inversión financiera | B35: - | C35: - | D35: 173.14431 | E35: - | F35: 106.2 | G35: - | H35: 613.3 | I35: 695.3 | J35: 276.80705 | K35: 116.52434 | L35: 92.807518 | M35: 595.77234 | N35: 86.483597 | O35: 30.199669 | P35: 68.9 | Q35: 110.92 | R35: 820.60447 | S35: 414.82085 | T35: 393.67024 | U35: 1298.3878 | V35: 913.83792 | W35: 592.10212 | X35: 4253.962 | Y35: 9174.8647 | Z35: 10306.808 | AA35: 6350.6 | AB35: 8755.6731 | AC35: 2571.19 | AD35: 17669.518 | AE35: 30528.485 | AF35: 70943.758 | AG35: 3175.5982
A36: Endeudamiento público e incremento de otros pasivos | B36: - | C36: - | D36: 898.11999 | E36: - | F36: - | G36: - | H36: - | I36: - | J36: 65.853383 | K36: 390.70361 | L36: 902.55067 | M36: 1388.5738 | N36: 2104.0821 | O36: 2461.8315 | P36: 1210 | Q36: 2329.9 | R36: 934 | S36: 2939.7176 | T36: 2377.935 | U36: 13275.513 | V36: 21194.991 | W36: 18529.132 | X36: 25381.881 | Y36: 6245.4465 | Z36: 19434.075 | AA36: 38957.2 | AB36: 35752.758 | AC36: 23019.632 | AD36: - | AE36: 21129.463 | AF36: 865699.98
A37: Ingresos no presupuestarios | B37: - | C37: - | D37: - | E37: - | F37: - | G37: - | H37: - | I37: - | J37: - | K37: - | L37: - | M37: - | N37: - | O37: - | P37: - | Q37: - | R37: - | S37: - | T37: - | U37: - | V37: - | W37: 3075.9008 | X37: 3432.3656 | Y37: 6344.3107 | Z37: 16946.172 | AA37: 8514.7 | AB37: 5441.9543 | AC37: 7138.5106 | AD37: 15366.098 | AE37: 1072674.8 | AF37: 490.58625
A38: 16) Aplicaciones financieras | B38: 567.6 | C38: 747 | D38: 899.87605 | E38: 386.3 | F38: 187.8 | G38: - | H38: 363 | I38: 606.9 | J38: 838.43586 | K38: 1372.7485 | L38: 1346.6651 | M38: 1326.249 | N38: 1854.2565 | O38: 2242.9481 | P38: 2242.9481 | Q38: 1534.1 | R38: 1901.8546 | S38: 1688.7793 | T38: 1364.5379 | U38: 10065.809 | V38: 14358.902 | W38: 14543.273 | X38: 20277.609 | Y38: 23136.902 | Z38: 35383.938 | AA38: 23011.7 | AB38: 47341.128 | AC38: 76859.08 | AD38: 71920.466 | AE38: 1431016.7 | AF38: 663100.92
A39: Incremento de la inversión financiera | B39: - | C39: - | D39: - | E39: - | F39: - | G39: - | H39: - | I39: - | J39: 720.18173 | K39: 1192.4244 | L39: 553.59155 | M39: 55.070253 | N39: 89.123411 | O39: 165.9792 | P39: 181.4 | Q39: 258 | R39: 296.02 | S39: 631.0765 | T39: 909.89612 | U39: 1177 | V39: 1354.3706 | W39: 1819.6008 | X39: 3161.5123 | Y39: 13314.124 | Z39: 23385.81 | AA39: 7996.1 | AB39: 8647.874 | AC39: 17746.202 | AD39: 36925.39 | AE39: 1355394.9 | AF39: 282500
A40: Amortización de la deuda y disminución de otros pasivos | B40: - | C40: - | D40: 899.87605 | E40: 386.3 | F40: 187.8 | G40: - | H40: 363 | I40: 606.9 | J40: 118.25413 | K40: 118.41264 | L40: 134.59203 | M40: 390.7822 | N40: 1765.1331 | O40: 1674.9222 | P40: 638.3 | Q40: 1276.1 | R40: 1605.8346 | S40: 1057.7028 | T40: 454.64176 | U40: 8888.8094 | V40: 13004.532 | W40: 12723.673 | X40: 17116.096 | Y40: 9822.7773 | Z40: 11998.128 | AA40: 15015.6 | AB40: 38693.254 | AC40: 59112.877 | AD40: 34995.076 | AE40: 75621.749 | AF40: 380600.92
A41: Nota: hasta 1997 los gastos se consideraron en la etapa definitiva, a partir de 1998 en la etapa devengado. Las diferencias con valores publicados anteriormente se deben a ajustes de elaboración. La suma de las cifras parciales difiere del total por procedimientos de redondeo. El dato provisorio contiene información de la Ejecución Presupuestaria.
...

Sheet ipc
A1: año | B1: tasa | C1: coef | D1: coefacum | F1: infla USD | H1: Nota: 2025-2026 = IPCBA dic/dic (oct-dic 2026 estimado al 2% mensual); 2027 = pauta 18% del proyecto. Base de coefacum: diciembre 2027.
A2: 1990 | B2: 13.439209 | C2: =B2+1 | D2: =PRODUCT(C3:$C$39)
A3: 1991 | B3: 0.83986931 | C3: =B3+1 | D3: =PRODUCT(C4:$C$39)
A4: 1992 | B4: 0.17545874 | C4: =B4+1 | D4: =PRODUCT(C5:$C$39)
A5: 1993 | B5: 0.073649811 | C5: =B5+1 | D5: =PRODUCT(C6:$C$39)
A6: 1994 | B6: 0.038543809 | C6: =B6+1 | D6: =PRODUCT(C7:$C$39)
A7: 1995 | B7: 0.016077542 | C7: =B7+1 | D7: =PRODUCT(C8:$C$39)
A8: 1996 | B8: 0.00054311345 | C8: =B8+1 | D8: =PRODUCT(C9:$C$39)
A9: 1997 | B9: 0.0032799692 | C9: =B9+1 | D9: =PRODUCT(C10:$C$39)
A10: 1998 | B10: 0.0066447893 | C10: =B10+1 | D10: =PRODUCT(C11:$C$39)
A11: 1999 | B11: -0.018104664 | C11: =B11+1 | D11: =PRODUCT(C12:$C$39)
A12: 2000 | B12: -0.0073369945 | C12: =B12+1 | D12: =PRODUCT(C13:$C$39)
A13: 2001 | B13: -0.015434278 | C13: =B13+1 | D13: =PRODUCT(C14:$C$39)
... A38: 2026 | B38: 0.31253381 | C38: =B38+1 | D38: =PRODUCT(C39:$C$39)
A39: 2027 | B39: 0.18 | C39: =B39+1 | D39: 1

Sheet constante
B1: 1995 | C1: 1996 | D1: 1997 | E1: 1998 | F1: 1999 | G1: 2000 | H1: 2001 | I1: 2002 | J1: 2003 | K1: 2004 | L1: 2005 | M1: 2006 | N1: 2007 | O1: 2008 | P1: 2009 | Q1: 2010 | R1: 2011 | S1: 2012 | T1: 2013 | U1: 2014 | V1: 2015 | W1: 2016 | X1: 2017 | Y1: 2018 | Z1: 2019 | AA1: 2020 | AB1: 2021 | AC1: 2022 | AD1: 2023 | AE1: 2024 | AF1: 2025 | AG1: 2027
A2: 1) Ingresos corrientes | B2: =IFERROR('dataset- CAIF corriente'!B4*VLOOKUP(constante!B$1,ipc!$A:$D,4,FALSE)/1000000,"") | C2: =IFERROR('dataset- CAIF corriente'!C4*VLOOKUP(constante!C$1,ipc!$A:$D,4,FALSE)/1000000,"") | D2: =IFERROR('dataset- CAIF corriente'!D4*VLOOKUP(constante!D$1,ipc!$A:$D,4,FALSE)/1000000,"") | E2: =IFERROR('dataset- CAIF corriente'!E4*VLOOKUP(constante!E$1,ipc!$A:$D,4,FALSE)/1000000,"") | F2: =IFERROR('dataset- CAIF corriente'!F4*VLOOKUP(constante!F$1,ipc!$A:$D,4,FALSE)/1000000,"") | G2: =IFERROR('dataset- CAIF corriente'!G4*VLOOKUP(constante!G$1,ipc!$A:$D,4,FALSE)/1000000,"") | H2: =IFERROR('dataset- CAIF corriente'!H4*VLOOKUP(constante!H$1,ipc!$A:$D,4,FALSE)/1000000,"") | I2: =IFERROR('dataset- CAIF corriente'!I4*VLOOKUP(constante!I$1,ipc!$A:$D,4,FALSE)/1000000,"") | ... AG2: =IFERROR('dataset- CAIF corriente'!AG4*VLOOKUP(constante!AG$1,ipc!$A:$D,4,FALSE)/1000000,"")
A3: Ingresos tributarios | B3: =IFERROR('dataset- CAIF corriente'!B5*VLOOKUP(constante!B$1,ipc!$A:$D,4,FALSE)/1000000,"") | C3: =IFERROR('dataset- CAIF corriente'!C5*VLOOKUP(constante!C$1,ipc!$A:$D,4,FALSE)/1000000,"") | D3: =IFERROR('dataset- CAIF corriente'!D5*VLOOKUP(constante!D$1,ipc!$A:$D,4,FALSE)/1000000,"") | E3: =IFERROR('dataset- CAIF corriente'!E5*VLOOKUP(constante!E$1,ipc!$A:$D,4,FALSE)/1000000,"") | F3: =IFERROR('dataset- CAIF corriente'!F5*VLOOKUP(constante!F$1,ipc!$A:$D,4,FALSE)/1000000,"") | G3: =IFERROR('dataset- CAIF corriente'!G5*VLOOKUP(constante!G$1,ipc!$A:$D,4,FALSE)/1000000,"") | H3: =IFERROR('dataset- CAIF corriente'!H5*VLOOKUP(constante!H$1,ipc!$A:$D,4,FALSE)/1000000,"") | I3: =IFERROR('dataset- CAIF corriente'!I5*VLOOKUP(constante!I$1,ipc!$A:$D,4,FALSE)/1000000,"") | ... AG3: =IFERROR('dataset- CAIF corriente'!AG5*VLOOKUP(constante!AG$1,ipc!$A:$D,4,FALSE)/1000000,"")
A4: Ingresos no tributarios | B4: =IFERROR('dataset- CAIF corriente'!B6*VLOOKUP(constante!B$1,ipc!$A:$D,4,FALSE)/1000000,"") | C4: =IFERROR('dataset- CAIF corriente'!C6*VLOOKUP(constante!C$1,ipc!$A:$D,4,FALSE)/1000000,"") | D4: =IFERROR('dataset- CAIF corriente'!D6*VLOOKUP(constante!D$1,ipc!$A:$D,4,FALSE)/1000000,"") | E4: =IFERROR('dataset- CAIF corriente'!E6*VLOOKUP(constante!E$1,ipc!$A:$D,4,FALSE)/1000000,"") | F4: =IFERROR('dataset- CAIF corriente'!F6*VLOOKUP(constante!F$1,ipc!$A:$D,4,FALSE)/1000000,"") | G4: =IFERROR('dataset- CAIF corriente'!G6*VLOOKUP(constante!G$1,ipc!$A:$D,4,FALSE)/1000000,"") | H4: =IFERROR('dataset- CAIF corriente'!H6*VLOOKUP(constante!H$1,ipc!$A:$D,4,FALSE)/1000000,"") | I4: =IFERROR('dataset- CAIF corriente'!I6*VLOOKUP(constante!I$1,ipc!$A:$D,4,FALSE)/1000000,"") | ... AG4: =IFERROR('dataset- CAIF corriente'!AG6*VLOOKUP(constante!AG$1,ipc!$A:$D,4,FALSE)/1000000,"")
A5: Venta de bienes y servicios | B5: =IFERROR('dataset- CAIF corriente'!B7*VLOOKUP(constante!B$1,ipc!$A:$D,4,FALSE)/1000000,"") | C5: =IFERROR('dataset- CAIF corriente'!C7*VLOOKUP(constante!C$1,ipc!$A:$D,4,FALSE)/1000000,"") | D5: =IFERROR('dataset- CAIF corriente'!D7*VLOOKUP(constante!D$1,ipc!$A:$D,4,FALSE)/1000000,"") | E5: =IFERROR('dataset- CAIF corriente'!E7*VLOOKUP(constante!E$1,ipc!$A:$D,4,FALSE)/1000000,"") | F5: =IFERROR('dataset- CAIF corriente'!F7*VLOOKUP(constante!F$1,ipc!$A:$D,4,FALSE)/1000000,"") | G5: =IFERROR('dataset- CAIF corriente'!G7*VLOOKUP(constante!G$1,ipc!$A:$D,4,FALSE)/1000000,"") | H5: =IFERROR('dataset- CAIF corriente'!H7*VLOOKUP(constante!H$1,ipc!$A:$D,4,FALSE)/1000000,"") | I5: =IFERROR('dataset- CAIF corriente'!I7*VLOOKUP(constante!I$1,ipc!$A:$D,4,FALSE)/1000000,"") | ... AG5: =IFERROR('dataset- CAIF corriente'!AG7*VLOOKUP(constante!AG$1,ipc!$A:$D,4,FALSE)/1000000,"")
A6: Rentas de la propiedad | B6: =IFERROR('dataset- CAIF corriente'!B8*VLOOKUP(constante!B$1,ipc!$A:$D,4,FALSE)/1000000,"") | C6: =IFERROR('dataset- CAIF corriente'!C8*VLOOKUP(constante!C$1,ipc!$A:$D,4,FALSE)/1000000,"") | D6: =IFERROR('dataset- CAIF corriente'!D8*VLOOKUP(constante!D$1,ipc!$A:$D,4,FALSE)/1000000,"") | E6: =IFERROR('dataset- CAIF corriente'!E8*VLOOKUP(constante!E$1,ipc!$A:$D,4,FALSE)/1000000,"") | F6: =IFERROR('dataset- CAIF corriente'!F8*VLOOKUP(constante!F$1,ipc!$A:$D,4,FALSE)/1000000,"") | G6: =IFERROR('dataset- CAIF corriente'!G8*VLOOKUP(constante!G$1,ipc!$A:$D,4,FALSE)/1000000,"") | H6: =IFERROR('dataset- CAIF corriente'!H8*VLOOKUP(constante!H$1,ipc!$A:$D,4,FALSE)/1000000,"") | I6: =IFERROR('dataset- CAIF corriente'!I8*VLOOKUP(constante!I$1,ipc!$A:$D,4,FALSE)/1000000,"") | ... AG6: =IFERROR('dataset- CAIF corriente'!AG8*VLOOKUP(constante!AG$1,ipc!$A:$D,4,FALSE)/1000000,"")
A7: Transferencias corrientes | B7: =IFERROR('dataset- CAIF corriente'!B9*VLOOKUP(constante!B$1,ipc!$A:$D,4,FALSE)/1000000,"") | C7: =IFERROR('dataset- CAIF corriente'!C9*VLOOKUP(constante!C$1,ipc!$A:$D,4,FALSE)/1000000,"") | D7: =IFERROR('dataset- CAIF corriente'!D9*VLOOKUP(constante!D$1,ipc!$A:$D,4,FALSE)/1000000,"") | E7: =IFERROR('dataset- CAIF corriente'!E9*VLOOKUP(constante!E$1,ipc!$A:$D,4,FALSE)/1000000,"") | F7: =IFERROR('dataset- CAIF corriente'!F9*VLOOKUP(constante!F$1,ipc!$A:$D,4,FALSE)/1000000,"") | G7: =IFERROR('dataset- CAIF corriente'!G9*VLOOKUP(constante!G$1,ipc!$A:$D,4,FALSE)/1000000,"") | H7: =IFERROR('dataset- CAIF corriente'!H9*VLOOKUP(constante!H$1,ipc!$A:$D,4,FALSE)/1000000,"") | I7: =IFERROR('dataset- CAIF corriente'!I9*VLOOKUP(constante!I$1,ipc!$A:$D,4,FALSE)/1000000,"") | ... AG7: =IFERROR('dataset- CAIF corriente'!AG9*VLOOKUP(constante!AG$1,ipc!$A:$D,4,FALSE)/1000000,"")
A8: 2) Gastos corrientes | B8: =IFERROR('dataset- CAIF corriente'!B10*VLOOKUP(constante!B$1,ipc!$A:$D,4,FALSE)/1000000,"") | C8: =IFERROR('dataset- CAIF corriente'!C10*VLOOKUP(constante!C$1,ipc!$A:$D,4,FALSE)/1000000,"") | D8: =IFERROR('dataset- CAIF corriente'!D10*VLOOKUP(constante!D$1,ipc!$A:$D,4,FALSE)/1000000,"") | E8: =IFERROR('dataset- CAIF corriente'!E10*VLOOKUP(constante!E$1,ipc!$A:$D,4,FALSE)/1000000,"") | F8: =IFERROR('dataset- CAIF corriente'!F10*VLOOKUP(constante!F$1,ipc!$A:$D,4,FALSE)/1000000,"") | G8: =IFERROR('dataset- CAIF corriente'!G10*VLOOKUP(constante!G$1,ipc!$A:$D,4,FALSE)/1000000,"") | H8: =IFERROR('dataset- CAIF corriente'!H10*VLOOKUP(constante!H$1,ipc!$A:$D,4,FALSE)/1000000,"") | I8: =IFERROR('dataset- CAIF corriente'!I10*VLOOKUP(constante!I$1,ipc!$A:$D,4,FALSE)/1000000,"") | ... AG8: =IFERROR('dataset- CAIF corriente'!AG10*VLOOKUP(constante!AG$1,ipc!$A:$D,4,FALSE)/1000000,"")
A9: Remuneraciones al personal | B9: =IFERROR('dataset- CAIF corriente'!B11*VLOOKUP(constante!B$1,ipc!$A:$D,4,FALSE)/1000000,"") | C9: =IFERROR('dataset- CAIF corriente'!C11*VLOOKUP(constante!C$1,ipc!$A:$D,4,FALSE)/1000000,"") | D9: =IFERROR('dataset- CAIF corriente'!D11*VLOOKUP(constante!D$1,ipc!$A:$D,4,FALSE)/1000000,"") | E9: =IFERROR('dataset- CAIF corriente'!E11*VLOOKUP(constante!E$1,ipc!$A:$D,4,FALSE)/1000000,"") | F9: =IFERROR('dataset- CAIF corriente'!F11*VLOOKUP(constante!F$1,ipc!$A:$D,4,FALSE)/1000000,"") | G9: =IFERROR('dataset- CAIF corriente'!G11*VLOOKUP(constante!G$1,ipc!$A:$D,4,FALSE)/1000000,"") | H9: =IFERROR('dataset- CAIF corriente'!H11*VLOOKUP(constante!H$1,ipc!$A:$D,4,FALSE)/1000000,"") | I9: =IFERROR('dataset- CAIF corriente'!I11*VLOOKUP(constante!I$1,ipc!$A:$D,4,FALSE)/1000000,"") | ... AG9: =IFERROR('dataset- CAIF corriente'!AG11*VLOOKUP(constante!AG$1,ipc!$A:$D,4,FALSE)/1000000,"")
A10: Gastos de consumo | B10: =IFERROR('dataset- CAIF corriente'!B12*VLOOKUP(constante!B$1,ipc!$A:$D,4,FALSE)/1000000,"") | C10: =IFERROR('dataset- CAIF corriente'!C12*VLOOKUP(constante!C$1,ipc!$A:$D,4,FALSE)/1000000,"") | D10: =IFERROR('dataset- CAIF corriente'!D12*VLOOKUP(constante!D$1,ipc!$A:$D,4,FALSE)/1000000,"") | E10: =IFERROR('dataset- CAIF corriente'!E12*VLOOKUP(constante!E$1,ipc!$A:$D,4,FALSE)/1000000,"") | F10: =IFERROR('dataset- CAIF corriente'!F12*VLOOKUP(constante!F$1,ipc!$A:$D,4,FALSE)/1000000,"") | G10: =IFERROR('dataset- CAIF corriente'!G12*VLOOKUP(constante!G$1,ipc!$A:$D,4,FALSE)/1000000,"") | H10: =IFERROR('dataset- CAIF corriente'!H12*VLOOKUP(constante!H$1,ipc!$A:$D,4,FALSE)/1000000,"") | I10: =IFERROR('dataset- CAIF corriente'!I12*VLOOKUP(constante!I$1,ipc!$A:$D,4,FALSE)/1000000,"") | ... AG10: =IFERROR('dataset- CAIF corriente'!AG12*VLOOKUP(constante!AG$1,ipc!$A:$D,4,FALSE)/1000000,"")
A11: Otras Pérdidas | B11: =IFERROR('dataset- CAIF corriente'!B13*VLOOKUP(constante!B$1,ipc!$A:$D,4,FALSE)/1000000,"") | C11: =IFERROR('dataset- CAIF corriente'!C13*VLOOKUP(constante!C$1,ipc!$A:$D,4,FALSE)/1000000,"") | D11: =IFERROR('dataset- CAIF corriente'!D13*VLOOKUP(constante!D$1,ipc!$A:$D,4,FALSE)/1000000,"") | E11: =IFERROR('dataset- CAIF corriente'!E13*VLOOKUP(constante!E$1,ipc!$A:$D,4,FALSE)/1000000,"") | F11: =IFERROR('dataset- CAIF corriente'!F13*VLOOKUP(constante!F$1,ipc!$A:$D,4,FALSE)/1000000,"") | G11: =IFERROR('dataset- CAIF corriente'!G13*VLOOKUP(constante!G$1,ipc!$A:$D,4,FALSE)/1000000,"") | H11: =IFERROR('dataset- CAIF corriente'!H13*VLOOKUP(constante!H$1,ipc!$A:$D,4,FALSE)/1000000,"") | I11: =IFERROR('dataset- CAIF corriente'!I13*VLOOKUP(constante!I$1,ipc!$A:$D,4,FALSE)/1000000,"") | ... AG11: =IFERROR('dataset- CAIF corriente'!AG13*VLOOKUP(constante!AG$1,ipc!$A:$D,4,FALSE)/1000000,"")
A12: Impuestos directos | B12: =IFERROR('dataset- CAIF corriente'!B14*VLOOKUP(constante!B$1,ipc!$A:$D,4,FALSE)/1000000,"") | C12: =IFERROR('dataset- CAIF corriente'!C14*VLOOKUP(constante!C$1,ipc!$A:$D,4,FALSE)/1000000,"") | D12: =IFERROR('dataset- CAIF corriente'!D14*VLOOKUP(constante!D$1,ipc!$A:$D,4,FALSE)/1000000,"") | E12: =IFERROR('dataset- CAIF corriente'!E14*VLOOKUP(constante!E$1,ipc!$A:$D,4,FALSE)/1000000,"") | F12: =IFERROR('dataset- CAIF corriente'!F14*VLOOKUP(constante!F$1,ipc!$A:$D,4,FALSE)/1000000,"") | G12: =IFERROR('dataset- CAIF corriente'!G14*VLOOKUP(constante!G$1,ipc!$A:$D,4,FALSE)/1000000,"") | H12: =IFERROR('dataset- CAIF corriente'!H14*VLOOKUP(constante!H$1,ipc!$A:$D,4,FALSE)/1000000,"") | I12: =IFERROR('dataset- CAIF corriente'!I14*VLOOKUP(constante!I$1,ipc!$A:$D,4,FALSE)/1000000,"") | ... AG12: =IFERROR('dataset- CAIF corriente'!AG14*VLOOKUP(constante!AG$1,ipc!$A:$D,4,FALSE)/1000000,"")
A13: Transferencias corrientes | B13: =IFERROR('dataset- CAIF corriente'!B15*VLOOKUP(constante!B$1,ipc!$A:$D,4,FALSE)/1000000,"") | C13: =IFERROR('dataset- CAIF corriente'!C15*VLOOKUP(constante!C$1,ipc!$A:$D,4,FALSE)/1000000,"") | D13: =IFERROR('dataset- CAIF corriente'!D15*VLOOKUP(constante!D$1,ipc!$A:$D,4,FALSE)/1000000,"") | E13: =IFERROR('dataset- CAIF corriente'!E15*VLOOKUP(constante!E$1,ipc!$A:$D,4,FALSE)/1000000,"") | F13: =IFERROR('dataset- CAIF corriente'!F15*VLOOKUP(constante!F$1,ipc!$A:$D,4,FALSE)/1000000,"") | G13: =IFERROR('dataset- CAIF corriente'!G15*VLOOKUP(constante!G$1,ipc!$A:$D,4,FALSE)/1000000,"") | H13: =IFERROR('dataset- CAIF corriente'!H15*VLOOKUP(constante!H$1,ipc!$A:$D,4,FALSE)/1000000,"") | I13: =IFERROR('dataset- CAIF corriente'!I15*VLOOKUP(constante!I$1,ipc!$A:$D,4,FALSE)/1000000,"") | ... AG13: =IFERROR('dataset- CAIF corriente'!AG15*VLOOKUP(constante!AG$1,ipc!$A:$D,4,FALSE)/1000000,"")
... A38: Amortización de la deuda y disminución de otros pasivos | B38: =IFERROR('dataset- CAIF corriente'!B40*VLOOKUP(constante!B$1,ipc!$A:$D,4,FALSE)/1000000,"") | C38: =IFERROR('dataset- CAIF corriente'!C40*VLOOKUP(constante!C$1,ipc!$A:$D,4,FALSE)/1000000,"") | D38: =IFERROR('dataset- CAIF corriente'!D40*VLOOKUP(constante!D$1,ipc!$A:$D,4,FALSE)/1000000,"") | E38: =IFERROR('dataset- CAIF corriente'!E40*VLOOKUP(constante!E$1,ipc!$A:$D,4,FALSE)/1000000,"") | F38: =IFERROR('dataset- CAIF corriente'!F40*VLOOKUP(constante!F$1,ipc!$A:$D,4,FALSE)/1000000,"") | G38: =IFERROR('dataset- CAIF corriente'!G40*VLOOKUP(constante!G$1,ipc!$A:$D,4,FALSE)/1000000,"") | H38: =IFERROR('dataset- CAIF corriente'!H40*VLOOKUP(constante!H$1,ipc!$A:$D,4,FALSE)/1000000,"") | I38: =IFERROR('dataset- CAIF corriente'!I40*VLOOKUP(constante!I$1,ipc!$A:$D,4,FALSE)/1000000,"") | ... AG38: =IFERROR('dataset- CAIF corriente'!AG40*VLOOKUP(constante!AG$1,ipc!$A:$D,4,FALSE)/1000000,"")
H39: = | N39: Macri | R39: =Y23/I23-1 | V39: Larreta | AD39: J. Macri
A40: Cambio de gestión | N40: 150 | V40: 150 | AD40: 150
A41: Resultado primario | B41: =B25/B23 | C41: =C25/C23 | D41: =D25/D23 | E41: =E25/E23 | F41: =F25/F23 | G41: =G25/G23 | H41: =H25/H23 | I41: =I25/I23 | ... AE41: =AE25/AE23
A42: Intereses de la deuda | B42: =B26/B23 | C42: =C26/C23 | D42: =D26/D23 | E42: =E26/E23 | F42: =F26/F23 | G42: =G26/G23 | H42: =H26/H23 | I42: =I26/I23 | ... AE42: =AE26/AE23
A43: Resultado financiero | B43: =B28/B23 | C43: =C28/C23 | D43: =D28/D23 | E43: =E28/E23 | F43: =F28/F23 | G43: =G28/G23 | H43: =H28/H23 | I43: =I28/I23 | ... AE43: =AE28/AE23
A78: recursos en billones | B78: =B23/1000000 | C78: =C23/1000000 | D78: =D23/1000000 | E78: =E23/1000000 | F78: =F23/1000000 | G78: =G23/1000000 | H78: =H23/1000000 | I78: =I23/1000000 | ... AE78: =AE23/1000000
A79: Resultado primario
A80: Recursos totales
A81: Gasto primario

Sheet dataset-titulos emitidos
A1: Títulos públicos emitidos por el Gobierno de la Ciudad de Buenos Aires. Años 2010/2024
A2: Títulos públicos | B2: 2010 | D2: 2011 | F2: 2012 | H2: 2013 | J2: 2014 | L2: 2015 | N2: 2016 | P2: 2017 | R2: 2018 | T2: 2019 | V2: 2020 | X2: 2021 | Z2: 2022 | AB2: 2023 | AD2: 2024
B3: Millones de pesos | C3: Millones de dólares | D3: Millones de pesos | E3: Millones de dólares | F3: Millones de pesos | G3: Millones de dólares | H3: Millones de pesos | I3: Millones de dólares | J3: Millones de pesos | K3: Millones de dólares | L3: Millones de pesos | M3: Millones de dólares | N3: Millones de pesos | O3: Millones de dólares | P3: Millones de pesos | Q3: Millones de dólares | R3: Millones de pesos | S3: Millones de dólares | T3: Millones de pesos | U3: Millones de dólares | V3: Millones de pesos | W3: Millones de dólares | X3: Millones de pesos | Y3: Millones de dólares | Z3: Millones de pesos | AA3: Millones de dólares | AB3: Millones de pesos | AC3: Millones de dólares | AD3: Millones de pesos | AE3: Millones de dólares
A4: Total | B4: 540.58554 | C4: 624.6375 | D4: 2.5351 | E4: 617.4664 | F4: 195.5673 | G4: 1133.573 | H4: 101.9539 | I4: 1549.606 | J4: 374.362 | K4: 1850.554 | L4: 1216.06 | M4: 1915.28 | N4: 4395.238 | O4: 2204.8482 | P4: 22259.266 | Q4: 1608.5596 | R4: 28304.362 | S4: 1466.7623 | T4: 47782.962 | U4: 1253.3728 | V4: 87988.185 | W4: 1071.4536 | X4: 100093.9 | Y4: 890 | Z4: 76636.1 | AA4: 890 | AB4: 61687.5 | AC4: 890 | AD4: 35684.2 | AE4: 890
A5: Bono Tango | B5: 7.5798 | C5: 624.6375 | D5: 2.5351 | E5: 617.4664 | F5: - | G5: 1133.573 | H5: - | I5: 932.7118 | J5: - | K5: 918.3425 | L5: - | M5: 945.77 | N5: - | O5: 1593.7082 | P5: - | Q5: 1412.5292 | R5: - | S5: 1412.5292 | T5: - | U5: 1241.9914 | V5: - | W5: 1071.4536 | X5: - | Y5: 890 | Z5: - | AA5: 890 | AB5: - | AC5: 890 | AD5: - | AE5: 890
A6: Certificado Cancelación de deuda - Ley 2810 | B6: 116.74024 | C6: - | D6: - | E6: - | F6: - | G6: - | H6: - | I6: - | J6: - | K6: - | L6: - | M6: - | N6: - | O6: - | P6: - | Q6: - | R6: - | S6: - | T6: - | U6: - | V6: - | W6: - | X6: - | Y6: - | Z6: - | AA6: - | AB6: - | AC6: - | AD6: - | AE6: -
A7: Bono Ley 3152 art. 1 | B7: 416.2655 | C7: - | D7: - | E7: - | F7: - | G7: - | H7: - | I7: - | J7: - | K7: - | L7: - | M7: - | N7: - | O7: - | P7: - | Q7: - | R7: - | S7: - | T7: - | U7: - | V7: - | W7: - | X7: - | Y7: - | Z7: - | AA7: - | AB7: - | AC7: - | AD7: - | AE7: -
A8: Bono Ley 4263 | B8: - | C8: - | D8: - | E8: - | F8: 195.5673 | G8: - | H8: 101.9539 | I8: - | J8: - | K8: - | L8: - | M8: - | N8: - | O8: - | P8: - | Q8: - | R8: - | S8: - | T8: - | U8: - | V8: - | W8: - | X8: - | Y8: - | Z8: - | AA8: - | AB8: - | AC8: - | AD8: - | AE8: -
A9: Bono Ley 5236 | B9: - | C9: - | D9: - | E9: - | F9: - | G9: - | H9: - | I9: - | J9: - | K9: - | L9: - | M9: - | N9: 1014.5361 | O9: - | P9: 344.8762 | Q9: - | R9: - | S9: - | T9: - | U9: - | V9: - | W9: - | X9: - | Y9: - | Z9: - | AA9: - | AB9: - | AC9: - | AD9: - | AE9: -
A10: Bono Ley 6282 y Ley 6300 | B10: - | C10: - | D10: - | E10: - | F10: - | G10: - | H10: - | I10: - | J10: - | K10: - | L10: - | M10: - | N10: - | O10: - | P10: - | Q10: - | R10: - | S10: - | T10: - | U10: - | V10: 19092.517 | W10: - | X10: 6105.1 | Y10: - | Z10: - | AA10: - | AB10: - | AC10: - | AD10: - | AE10: -
A11: Bono Ley 6385 | B11: - | C11: - | D11: - | E11: - | F11: - | G11: - | H11: - | I11: - | J11: - | K11: - | L11: - | M11: - | N11: - | O11: - | P11: - | Q11: - | R11: - | S11: - | T11: - | U11: - | V11: - | W11: - | X11: 14350.8 | Y11: - | Z11: 14948.6 | AA11: - | AB11: - | AC11: - | AD11: - | AE11: -
A12: Bono de Conversión Ley 6410 | B12: - | C12: - | D12: - | E12: - | F12: - | G12: - | H12: - | I12: - | J12: - | K12: - | L12: - | M12: - | N12: - | O12: - | P12: - | Q12: - | R12: - | S12: - | T12: - | U12: - | V12: - | W12: - | Z12: 4874.3 | AA12: - | AB12: 4874.3 | AC12: - | AD12: 4874.3 | AE12: -
A13: Letras del Tesoro | B13: - | C13: - | D13: - | E13: - | F13: - | G13: - | H13: - | I13: - | J13: - | K13: - | L13: - | M13: - | N13: - | O13: - | P13: - | Q13: - | R13: - | S13: - | T13: - | U13: - | V13: - | W13: - | X13: 12000 | Y13: - | Z13: - | AA13: - | AB13: - | AC13: - | AD13: - | AE13: -
A14: Programa de Financiamiento Mercado local | B14: - | C14: - | D14: - | E14: - | F14: - | G14: - | H14: - | I14: 616.8942 | J14: 374.362 | K14: 932.2115 | L14: 1216.06 | M14: 969.51 | N14: 3380.7019 | O14: 611.14 | P14: 21914.39 | Q14: 196.0304 | R14: 28304.362 | S14: 54.2331 | T14: 47782.962 | U14: 11.3814 | V14: 68895.668 | W14: - | X14: 67638 | Y14: - | Z14: 56813.1 | AA14: - | AB14: 56813.2 | AC14: - | AD14: 30809.9 | AE14: -
A15: Bono Ley 4315 - Clase 1 | B15: - | C15: - | D15: - | E15: - | F15: - | G15: - | H15: - | I15: 101.4133 | J15: - | K15: - | L15: - | M15: - | N15: - | O15: - | P15: - | Q15: - | R15: - | S15: - | T15: - | U15: - | V15: - | W15: - | X15: - | Y15: - | Z15: - | AA15: - | AB15: - | AC15: - | AD15: - | AE15: -
A16: Bono Leyes 4315 y 4431 - Clase 2 | B16: - | C16: - | D16: - | E16: - | F16: - | G16: - | H16: - | I16: 85.0799 | J16: - | K16: - | L16: - | M16: - | N16: - | O16: - | P16: - | Q16: - | R16: - | S16: - | T16: - | U16: - | V16: - | W16: - | X16: - | Y16: - | Z16: - | AA16: - | AB16: - | AC16: - | AD16: - | AE16: -
A17: Bono Ley 4472 - Clase 3 | B17: - | C17: - | D17: - | E17: - | F17: - | G17: - | H17: - | I17: 100.0238 | J17: - | K17: 101.194 | L17: - | M17: 101.19 | N17: - | O17: 75.8955 | P17: - | Q17: 7.9547 | R17: - | S17: - | T17: - | U17: - | V17: - | W17: - | X17: - | Y17: - | Z17: - | AA17: - | AB17: - | AC17: - | AD17: - | AE17: -
A18: Bono Leyes 4382 y 4885 - Clase 4 | B18: - | C18: - | D18: - | E18: - | F18: - | G18: - | H18: - | I18: 217.0746 | J18: - | K18: 328.7193 | L18: - | M18: 328.72 | N18: - | O18: 273.9218 | P18: - | Q18: 45.0228 | R18: - | S18: 11.384 | T18: - | U18: - | V18: - | W18: - | X18: - | Y18: - | Z18: - | AA18: - | AB18: - | AC18: - | AD18: - | AE18: -
A19: Bono Ley 4810 - Clase 5 | B19: - | C19: - | D19: - | E19: - | F19: - | G19: - | H19: - | I19: 113.3026 | J19: - | K19: 113.3026 | L19: - | M19: 113.3 | N19: - | O19: 113.3035 | P19: - | Q19: 19.7128 | R19: - | S19: 8.6778 | T19: - | U19: - | V19: - | W19: - | X19: - | Y19: - | Z19: - | AA19: - | AB19: - | AC19: - | AD19: - | AE19: -
A20: Bono Ley 4810 - Clase 6 | B20: - | C20: - | D20: - | E20: - | F20: - | G20: - | H20: - | I20: - | J20: - | K20: 148.0192 | L20: - | M20: 148.02 | N20: - | O20: 148.0192 | P20: - | Q20: 123.3401 | R20: - | S20: 34.1713 | T20: - | U20: 11.3814 | V20: - | W20: - | X20: - | Y20: - | Z20: - | AA20: - | AB20: - | AC20: - | AD20: - | AE20: -
A21: Bono Ley 4472 - Clase 7 | B21: - | C21: - | D21: - | E21: - | F21: - | G21: - | H21: - | I21: - | J21: - | K21: 100.6993 | L21: - | M21: 100.7 | N21: - | O21: - | P21: - | Q21: - | R21: - | S21: - | T21: - | U21: - | V21: - | W21: - | X21: - | Y21: - | Z21: - | AA21: - | AB21: - | AC21: - | AD21: - | AE21: -
A22: Bono Ley 4472 - Clase 8 | B22: - | C22: - | D22: - | E22: - | F22: - | G22: - | H22: - | I22: - | J22: - | K22: 75.619 | L22: - | M22: 75.62 | N22: - | O22: - | P22: - | Q22: - | R22: - | S22: - | T22: - | U22: - | V22: - | W22: - | X22: - | Y22: - | Z22: - | AA22: - | AB22: - | AC22: - | AD22: - | AE22: -
A23: Bono Ley 4472 - Clase 9 | B23: - | C23: - | D23: - | E23: - | F23: - | G23: - | H23: - | I23: - | J23: 196.4753 | K23: - | L23: 196.68 | M23: - | N23: - | O23: - | P23: - | Q23: - | R23: - | S23: - | T23: - | U23: - | V23: - | W23: - | X23: - | Y23: - | Z23: - | AA23: - | AB23: - | AC23: - | AD23: - | AE23: -
A24: Bono Ley 4472 - Clase 10 | B24: - | C24: - | D24: - | E24: - | F24: - | G24: - | H24: - | I24: - | J24: - | K24: 64.6581 | L24: - | M24: 64.66 | N24: - | O24: - | P24: - | Q24: - | R24: - | S24: - | T24: - | U24: - | V24: - | W24: - | X24: - | Y24: - | Z24: - | AA24: - | AB24: - | AC24: - | AD24: - | AE24: -
A25: Bono Ley 4472 - Clase 11 | B25: - | C25: - | D25: - | E25: - | F25: - | G25: - | H25: - | I25: - | J25: 177.8867 | K25: - | L25: 178.93 | M25: 0 | N25: - | O25: - | P25: - | Q25: - | R25: - | S25: - | T25: - | U25: - | V25: - | W25: - | X25: - | Y25: - | Z25: - | AA25: - | AB25: - | AC25: - | AD25: - | AE25: -
A26: Bono Ley 4472 - Clase 12 | B26: - | C26: - | D26: - | E26: - | F26: - | G26: - | H26: - | I26: - | J26: - | K26: - | L26: - | M26: 37.3 | N26: - | O26: - | P26: - | Q26: - | R26: - | S26: - | T26: - | U26: - | V26: - | W26: - | X26: - | Y26: - | Z26: - | AA26: - | AB26: - | AC26: - | AD26: - | AE26: -
A27: Bono Ley 4472 - Clase 13 | B27: - | C27: - | D27: - | E27: - | F27: - | G27: - | H27: - | I27: - | J27: - | K27: - | L27: 471.19 | M27: - | N27: - | O27: - | P27: - | Q27: - | R27: - | S27: - | T27: - | U27: - | V27: - | W27: - | X27: - | Y27: - | Z27: - | AA27: - | AB27: - | AC27: - | AD27: - | AE27: -
A28: Bono Ley 4472 - Clase 14 | B28: - | C28: - | D28: - | E28: - | F28: - | G28: - | H28: - | I28: - | J28: - | K28: - | L28: 105.75 | M28: - | N28: 105.096 | O28: - | P28: 14.7578 | Q28: - | R28: - | S28: - | T28: - | U28: - | V28: - | W28: - | X28: - | Y28: - | Z28: - | AA28: - | AB28: - | AC28: - | AD28: - | AE28: -
A29: Bono Ley 4472 - Clase 15 | B29: - | C29: - | D29: - | E29: - | F29: - | G29: - | H29: - | I29: - | J29: - | K29: - | L29: 263.51 | M29: - | N29: 158.0583 | O29: - | P29: 21.9288 | Q29: - | R29: - | S29: - | T29: - | U29: - | V29: - | W29: - | X29: - | Y29: - | Z29: - | AA29: - | AB29: - | AC29: - | AD29: - | AE29: -
A30: Bono Ley 5496 - Clase 16 | B30: - | C30: - | D30: - | E30: - | F30: - | G30: - | H30: - | I30: - | J30: - | K30: - | L30: - | M30: - | N30: 987.4806 | O30: - | P30: 265.8611 | Q30: - | R30: 207.8383 | S30: - | T30: 68.6214 | U30: - | V30: - | W30: - | X30: - | Y30: - | Z30: - | AA30: - | AB30: - | AC30: - | AD30: - | AE30: -
A31: Bono Ley 5491 - Clase 17 | B31: - | C31: - | D31: - | E31: - | F31: - | G31: - | H31: - | I31: - | J31: - | K31: - | L31: - | M31: - | N31: 374.0368 | O31: - | P31: - | Q31: - | R31: - | S31: - | T31: - | U31: - | V31: - | W31: - | X31: - | Y31: - | Z31: - | AA31: - | AB31: - | AC31: - | AD31: - | AE31: -
A32: Bono Ley 5491 - Clase 18 | B32: - | C32: - | D32: - | E32: - | F32: - | G32: - | H32: - | I32: - | J32: - | K32: - | L32: - | M32: - | N32: 1756.0302 | O32: - | P32: 805.2031 | Q32: - | R32: 525.878 | S32: - | T32: 173.8534 | U32: - | V32: - | W32: - | X32: - | Y32: - | Z32: - | AA32: - | AB32: - | AC32: - | AD32: - | AE32: -
A33: Bono Ley 5491 - Clase 19 | B33: - | C33: - | D33: - | E33: - | F33: - | G33: - | H33: - | I33: - | J33: - | K33: - | L33: - | M33: - | N33: - | O33: - | P33: 164.2754 | Q33: - | R33: - | S33: - | T33: - | U33: - | V33: - | W33: - | X33: - | Y33: - | Z33: - | AA33: - | AB33: - | AC33: - | AD33: - | AE33: -
A34: Bono Ley 5491 - Clase 20 | B34: - | C34: - | D34: - | E34: - | F34: - | G34: - | H34: - | I34: - | J34: - | K34: - | L34: - | M34: - | N34: - | O34: - | P34: 3904.4523 | Q34: - | R34: 4099.7298 | S34: - | T34: 10928.847 | U34: - | V34: 20784.689 | W34: - | X34: 10772.1 | Y34: - | Z34: - | AA34: - | AB34: - | AC34: - | AD34: - | AE34: -
A35: Bono Leyes 5541-5725 y 5727 - Clase 22 | B35: - | C35: - | D35: - | E35: - | F35: - | G35: - | H35: - | I35: - | J35: - | K35: - | L35: - | M35: - | N35: - | O35: - | P35: 9449.5146 | Q35: - | R35: 9465.205 | S35: - | T35: 22714.491 | U35: - | V35: 34299.683 | W35: - | X35: 43603.4 | Y35: - | Z35: 26003.2 | AA35: - | AB35: 26003.3 | AC35: - | AD35: - | AE35: -
A36: Bono Ley 5876 - Clase 23 | B36: - | C36: - | D36: - | E36: - | F36: - | G36: - | H36: - | I36: - | J36: - | K36: - | L36: - | M36: - | N36: - | O36: - | P36: 7288.3968 | Q36: - | R36: 14005.711 | S36: - | T36: 13897.148 | U36: - | V36: 13811.296 | W36: - | X36: 13262.5 | Y36: - | Z36: 30809.9 | AA36: - | AB36: 30809.9 | AC36: - | AD36: 30810 | AE36: -
B38: =B2 | C38: =B38 | D38: =D2 | E38: =D38 | F38: =F2 | G38: =F38 | H38: =H2 | I38: =H38 | J38: =J2 | K38: =J38 | L38: =L2 | M38: =L38 | N38: =N2 | O38: =N38 | P38: =P2 | Q38: =P38 | R38: =R2 | S38: =R38 | T38: =T2 | U38: =T38 | V38: =V2 | W38: =V38 | X38: =X2 | Y38: =X38 | Z38: =Z2 | AA38: =Z38 | AB38: =AB2 | AC38: =AB38 | AD38: =AD2 | AE38: =AD38
B39: =IF(B3="Millones de pesos","ARS","USD") | C39: =IF(C3="Millones de pesos","ARS","USD") | D39: =IF(D3="Millones de pesos","ARS","USD") | E39: =IF(E3="Millones de pesos","ARS","USD") | F39: =IF(F3="Millones de pesos","ARS","USD") | G39: =IF(G3="Millones de pesos","ARS","USD") | H39: =IF(H3="Millones de pesos","ARS","USD") | I39: =IF(I3="Millones de pesos","ARS","USD") | ... AE39: =IF(AE3="Millones de pesos","ARS","USD")
B40: =B4 | C40: =C4 | D40: =D4 | E40: =E4 | F40: =F4 | G40: =G4 | H40: =H4 | I40: =I4 | ... AE40: =AE4

Sheet emisiones
A1: año | B1: moneda | C1: monto | D1: constante | G1: ARS | H1: USD
A2: 2010 | B2: ARS | C2: 540.58554 | D2: =IF(B2="ARS",emisiones!C2*VLOOKUP(A2,ipc!$A:$D,4,FALSE),emisiones!C2) | F2: 2010 | G2: =SUMIFS($D:$D,$A:$A,$F2,$B:$B,G$1) | H2: =SUMIFS($D:$D,$A:$A,$F2,$B:$B,H$1)
A3: 2010 | B3: USD | C3: 624.6375 | D3: =IF(B3="ARS",emisiones!C3*VLOOKUP(A3,ipc!$A:$D,4,FALSE),emisiones!C3) | F3: 2011 | G3: =SUMIFS($D:$D,$A:$A,$F3,$B:$B,G$1) | H3: =SUMIFS($D:$D,$A:$A,$F3,$B:$B,H$1)
A4: 2011 | B4: ARS | C4: 2.5351 | D4: =IF(B4="ARS",emisiones!C4*VLOOKUP(A4,ipc!$A:$D,4,FALSE),emisiones!C4) | F4: 2012 | G4: =SUMIFS($D:$D,$A:$A,$F4,$B:$B,G$1) | H4: =SUMIFS($D:$D,$A:$A,$F4,$B:$B,H$1)
A5: 2011 | B5: USD | C5: 617.4664 | D5: =IF(B5="ARS",emisiones!C5*VLOOKUP(A5,ipc!$A:$D,4,FALSE),emisiones!C5) | F5: 2013 | G5: =SUMIFS($D:$D,$A:$A,$F5,$B:$B,G$1) | H5: =SUMIFS($D:$D,$A:$A,$F5,$B:$B,H$1)
A6: 2012 | B6: ARS | C6: 195.5673 | D6: =IF(B6="ARS",emisiones!C6*VLOOKUP(A6,ipc!$A:$D,4,FALSE),emisiones!C6) | F6: 2014 | G6: =SUMIFS($D:$D,$A:$A,$F6,$B:$B,G$1) | H6: =SUMIFS($D:$D,$A:$A,$F6,$B:$B,H$1)
A7: 2012 | B7: USD | C7: 1133.573 | D7: =IF(B7="ARS",emisiones!C7*VLOOKUP(A7,ipc!$A:$D,4,FALSE),emisiones!C7) | F7: 2015 | G7: =SUMIFS($D:$D,$A:$A,$F7,$B:$B,G$1) | H7: =SUMIFS($D:$D,$A:$A,$F7,$B:$B,H$1)
A8: 2013 | B8: ARS | C8: 101.9539 | D8: =IF(B8="ARS",emisiones!C8*VLOOKUP(A8,ipc!$A:$D,4,FALSE),emisiones!C8) | F8: 2016 | G8: =SUMIFS($D:$D,$A:$A,$F8,$B:$B,G$1) | H8: =SUMIFS($D:$D,$A:$A,$F8,$B:$B,H$1)
A9: 2013 | B9: USD | C9: 1549.606 | D9: =IF(B9="ARS",emisiones!C9*VLOOKUP(A9,ipc!$A:$D,4,FALSE),emisiones!C9) | F9: 2017 | G9: =SUMIFS($D:$D,$A:$A,$F9,$B:$B,G$1) | H9: =SUMIFS($D:$D,$A:$A,$F9,$B:$B,H$1)
A10: 2014 | B10: ARS | C10: 374.362 | D10: =IF(B10="ARS",emisiones!C10*VLOOKUP(A10,ipc!$A:$D,4,FALSE),emisiones!C10) | F10: 2018 | G10: =SUMIFS($D:$D,$A:$A,$F10,$B:$B,G$1) | H10: =SUMIFS($D:$D,$A:$A,$F10,$B:$B,H$1)
A11: 2014 | B11: USD | C11: 1850.554 | D11: =IF(B11="ARS",emisiones!C11*VLOOKUP(A11,ipc!$A:$D,4,FALSE),emisiones!C11) | F11: 2019 | G11: =SUMIFS($D:$D,$A:$A,$F11,$B:$B,G$1) | H11: =SUMIFS($D:$D,$A:$A,$F11,$B:$B,H$1)
A12: 2015 | B12: ARS | C12: 1216.06 | D12: =IF(B12="ARS",emisiones!C12*VLOOKUP(A12,ipc!$A:$D,4,FALSE),emisiones!C12) | F12: 2020 | G12: =SUMIFS($D:$D,$A:$A,$F12,$B:$B,G$1) | H12: =SUMIFS($D:$D,$A:$A,$F12,$B:$B,H$1)
A13: 2015 | B13: USD | C13: 1915.28 | D13: =IF(B13="ARS",emisiones!C13*VLOOKUP(A13,ipc!$A:$D,4,FALSE),emisiones!C13) | F13: 2021 | G13: =SUMIFS($D:$D,$A:$A,$F13,$B:$B,G$1) | H13: =SUMIFS($D:$D,$A:$A,$F13,$B:$B,H$1)
... A16: 2017 | B16: ARS | C16: 22259.266 | D16: =IF(B16="ARS",emisiones!C16*VLOOKUP(A16,ipc!$A:$D,4,FALSE),emisiones!C16) | F16: 2024 | G16: =SUMIFS($D:$D,$A:$A,$F16,$B:$B,G$1) | H16: =SUMIFS($D:$D,$A:$A,$F16,$B:$B,H$1)
A17: 2017 | B17: USD | C17: 1608.5596 | D17: =IF(B17="ARS",emisiones!C17*VLOOKUP(A17,ipc!$A:$D,4,FALSE),emisiones!C17)
A18: 2018 | B18: ARS | C18: 28304.362 | D18: =IF(B18="ARS",emisiones!C18*VLOOKUP(A18,ipc!$A:$D,4,FALSE),emisiones!C18)
A19: 2018 | B19: USD | C19: 1466.7623 | D19: =IF(B19="ARS",emisiones!C19*VLOOKUP(A19,ipc!$A:$D,4,FALSE),emisiones!C19)
A20: 2019 | B20: ARS | C20: 47782.962 | D20: =IF(B20="ARS",emisiones!C20*VLOOKUP(A20,ipc!$A:$D,4,FALSE),emisiones!C20)
A21: 2019 | B21: USD | C21: 1253.3728 | D21: =IF(B21="ARS",emisiones!C21*VLOOKUP(A21,ipc!$A:$D,4,FALSE),emisiones!C21)
A22: 2020 | B22: ARS | C22: 87988.185 | D22: =IF(B22="ARS",emisiones!C22*VLOOKUP(A22,ipc!$A:$D,4,FALSE),emisiones!C22)
A23: 2020 | B23: USD | C23: 1071.4536 | D23: =IF(B23="ARS",emisiones!C23*VLOOKUP(A23,ipc!$A:$D,4,FALSE),emisiones!C23)
A24: 2021 | B24: ARS | C24: 100093.9 | D24: =IF(B24="ARS",emisiones!C24*VLOOKUP(A24,ipc!$A:$D,4,FALSE),emisiones!C24)
A25: 2021 | B25: USD | C25: 890 | D25: =IF(B25="ARS",emisiones!C25*VLOOKUP(A25,ipc!$A:$D,4,FALSE),emisiones!C25)
A26: 2022 | B26: ARS | C26: 76636.1 | D26: =IF(B26="ARS",emisiones!C26*VLOOKUP(A26,ipc!$A:$D,4,FALSE),emisiones!C26)
A27: 2022 | B27: USD | C27: 890 | D27: =IF(B27="ARS",emisiones!C27*VLOOKUP(A27,ipc!$A:$D,4,FALSE),emisiones!C27)
A28: 2023 | B28: ARS | C28: 61687.5 | D28: =IF(B28="ARS",emisiones!C28*VLOOKUP(A28,ipc!$A:$D,4,FALSE),emisiones!C28)
... A31: 2024 | B31: USD | C31: 890 | D31: =IF(B31="ARS",emisiones!C31*VLOOKUP(A31,ipc!$A:$D,4,FALSE),emisiones!C31)

Sheet dataset-stock de deuda
A1: Tipo de deuda | B1: 1996 | C1: 1997 | D1: 1998 | E1: 1999 | F1: 2000 | G1: 2001 | H1: 2002 | M1: 2003 | Q1: 2004 | U1: 2005 | Y1: 2006 | AC1: 2007 | AG1: 2008 | AK1: 2009 | AO1: 2010 | AS1: 2011 | AV1: 2012 | AZ1: 2013 | BE1: 2014 | BH1: 2015 | BL1: 2016 | BP1: 2017 | BT1: 2018 | BY1: 2019 | CD1: 2020 | CI1: 2021 | CN1: 2022 | CS1: 2023 | CX1: 2024
B2: Millones de pesos | H2: Total en millones de pesos1 | I2: Millones de pesos | J2: Millones de dólares | K2: Millones de euros | L2: Total en millones de pesos1 | M2: Millones de pesos | N2: Millones de dólares | O2: Millones de euros | P2: Total en millones de pesos1 | Q2: Millones de pesos | R2: Millones de dólares | S2: Millones de euros | T2: Total en millones de pesos1 | U2: Millones de pesos | V2: Millones de dólares | W2: Millones de euros | X2: Total en millones de pesos1 | Y2: Millones de pesos | Z2: Millones de dólares | AA2: Millones de euros | AB2: Total en millones de pesos1 | AC2: Millones de pesos | AD2: Millones de dólares | AE2: Millones de euros | AF2: Total en millones de pesos1 | AG2: Millones de pesos | AH2: Millones de dólares | AI2: Millones de euros | AJ2: Total en millones de pesos1 | AK2: Millones de pesos | AL2: Millones de dólares | AM2: Millones de euros | AN2: Total en millones de pesos1 | AO2: Millones de pesos | AP2: Millones de dólares | AQ2: Millones de euros | AR2: Total en millones de pesos1 | AS2: Millones de pesos | AT2: Millones de dólares | AU2: Millones de euros | AV2: Millones de pesos | AW2: Total en millones de pesos1 | AX2: Millones de dólares | AY2: Millones de euros | AZ2: Millones de pesos | BA2: Total en millones de pesos1 | BB2: Millones de dólares | BC2: Millones de euros | BD2: Total en millones de pesos1 | BE2: Millones de pesos | BF2: Millones de dólares | BG2: Millones de euros | BH2: Total en millones de pesos1 | BI2: Millones de pesos | BJ2: Millones de dólares | BK2: Millones de euros | BL2: Total en millones de pesos1 | BM2: Millones de pesos | BN2: Millones de dólares | BO2: Millones de euros | BP2: Total en millones de pesos1 | BQ2: Millones de pesos | BR2: Millones de dólares | BS2: Millones de euros | BT2: Total en millones de pesos1 | BU2: Millones de pesos | BV2: Millones de dólares | BW2: Millones de euros | BX2: UVAs | BY2: Total en millones de pesos1 | BZ2: Millones de pesos | CA2: Millones de dólares | CB2: Millones de euros | CC2: UVAs | CD2: Total en millones de pesos1 | CE2: Millones de pesos | CF2: Millones de dólares | CG2: Millones de euros | CH2: UVAs | CI2: Total en millones de pesos1 | CJ2: Millones de pesos | CK2: Millones de dólares | CL2: Millones de euros | CM2: UVAs | CN2: Total en millones de pesos1 | CO2: Millones de pesos | CP2: Millones de dólares | CQ2: Millones de euros | CR2: UVAs | CS2: Total en millones de pesos1 | CT2: Millones de pesos | CU2: Millones de dólares | CV2: Millones de euros | CW2: UVAs | CX2: Total en millones de pesos1 | CY2: Millones de pesos | CZ2: Millones de dólares | DA2: Millones de euros | DB2: UVAs
A3: Total | B3: 1000.6 | C3: 1162.1 | D3: 1035.5539 | E3: 825.66 | F3: 1201.86 | G3: 1438.73 | H3: 2928.0004 | I3: 12.5 | J3: 93.84 | K3: 197.21 | L3: 2162.1637 | M3: 702.12 | N3: 361.74 | O3: 199.15 | P3: 2687.8195 | Q3: 795.2149 | R3: 366.3913 | S3: 197.3603 | T3: 3190.8206 | U3: 1441.5514 | V3: 371.8647 | W3: 173.3249 | X3: 3069.7333 | Y3: 1382.2263 | Z3: 404.6549 | AA3: 107.9317 | AB3: 2722.1199 | AC3: 1096.9815 | AD3: 452.143 | AE3: 43.4719 | AF3: 3688.0461 | AG3: 2070.2912 | AH3: 441.9628 | AI3: 19.0719 | AJ3: 4899.3707 | AK3: 3288.2338 | AL3: 389.0427 | AM3: 24.3778 | AN3: 6861.7634 | AO3: 3466.9338 | AP3: 775.2832 | AQ3: 58.7884 | AR3: 6573.0955 | AS3: 2874.3102 | AT3: 752.5825 | AU3: 85.5177 | AV3: 11269.585 | AW3: 4448.0121 | AX3: 1257.4379 | AY3: 98.2004 | AZ3: =SUM(AZ4:AZ11) | BA3: 5537.6168 | BB3: 1655.3117 | BC3: 98.0992 | BD3: =SUM(BD4:BD11) | BE3: 8858.3512 | BF3: 1937.3886 | BG3: 97.0158 | BH3: =SUM(BH4:BH11) | BI3: 13482.36 | BJ3: 2145.18 | BK3: 92.09 | BL3: 71481.534 | BM3: 30608.838 | BN3: 2368.0966 | BO3: 78.3 | BP3: 94209.94 | BQ3: 54820.381 | BR3: 2043.4387 | BS3: 57.0388 | BT3: 146236.79 | BU3: 67192.661 | BV3: 2021.9206 | BW3: 33.8075 | BX3: 43.7958 | BY3: 226096.42 | BZ3: 99971.784 | CA3: 2064.4822 | CB3: 14.0388 | CC3: 32.6 | CD3: 324857.85 | CE3: 158134.02 | CF3: 1957.6599 | CG3: - | CH3: 30.8885 | CI3: 271752.92 | CJ3: 108562.8 | CK3: 1488 | CL3: - | CM3: 29.311 | CN3: 363796.56 | CO3: 80123.2 | CP3: =SUM(CP4:CP12) | CQ3: - | CR3: =SUM(CR4:CR12) | CS3: 1336868.4 | CT3: 62225.5 | CU3: 1539 | CV3: - | CW3: - | CX3: 1618579.4 | CY3: 36007.1 | CZ3: 1503.6 | DA3: - | DB3: -
A4: Proveedores y Contratistas | B4: 481.3 | C4: 420.6 | D4: 396.49445 | E4: 201.7 | F4: 483.73 | G4: 655.35 | H4: 665.2 | I4: 665.16 | J4: - | K4: - | L4: 356.4 | M4: 356.44 | N4: - | O4: - | P4: 454.59 | Q4: 454.59 | R4: - | S4: - | T4: 970.17 | U4: 970.17 | V4: - | W4: - | X4: 1164.316 | Y4: 1164.316 | Z4: - | AA4: - | AB4: 962.4667 | AC4: 962.4667 | AD4: - | AE4: - | AF4: 1975.3239 | AG4: 1975.3239 | AH4: - | AI4: - | AJ4: 2326.3446 | AK4: 2326.3446 | AL4: - | AM4: - | AN4: 2349.6618 | AO4: 2349.6618 | AP4: - | AQ4: - | AR4: 2464.0965 | AS4: 2457.9494 | AT4: 1.4359 | AU4: - | AV4: 4146.9243 | AW4: 4112.6065 | AX4: 6.978 | AY4: - | AZ4: 5387.7169 | BA4: 5352.538 | BB4: 5.3914 | BC4: - | BD4: 8020.3869 | BE4: 7994.0669 | BF4: 3.078 | BG4: - | BH4: 9793.8496 | BI4: 9787.46 | BJ4: 0.49 | BK4: - | BL4: 21985.208 | BM4: 21982.85 | BN4: 0.1484 | BO4: - | BP4: 24439.06 | BQ4: 24439.06 | BR4: - | BS4: - | BT4: 33107.785 | BU4: 33063.031 | BV4: 1.18663 | BW4: - | BX4: - | BY4: 43502.433 | BZ4: 43464.534 | CA4: 0.6193 | CB4: - | CC4: - | CD4: 61308.927 | CE4: 61308.927 | CF4: - | CG4: - | CH4: - | CI4: - | CJ4: - | CK4: - | CL4: - | CM4: - | CN4: - | CO4: - | CP4: - | CQ4: - | CR4: - | CS4: - | CT4: - | CU4: - | CV4: - | CW4: - | CX4: - | CY4: - | CZ4: - | DA4: - | DB4: -
A5: Deuda previsional | B5: - | C5: - | D5: - | E5: 62 | F5: 96.9 | G5: 89.09 | H5: 87.88 | I5: 87.88 | J5: - | K5: - | L5: 64.02 | M5: 64.02 | N5: - | O5: - | P5: 38.92 | Q5: 38.92 | R5: - | S5: - | T5: 35.9 | U5: 35.8677 | V5: - | W5: - | X5: 34.2876 | Y5: 34.2876 | Z5: - | AA5: - | AB5: 34.1133 | AC5: 34.1133 | AD5: - | AE5: - | AF5: 33.5211 | AG5: 33.5211 | AH5: - | AI5: - | AJ5: 33.1605 | AK5: 33.1605 | AL5: - | AM5: - | AN5: 32.7616 | AO5: 32.7616 | AP5: - | AQ5: - | AR5: 32.6701 | AS5: 32.6701 | AT5: - | AU5: - | AV5: 32.611 | AW5: 32.611 | AX5: - | AY5: - | AZ5: 32.7004 | BA5: 32.7004 | BB5: - | BC5: - | BD5: 32.7549 | BE5: 32.7549 | BF5: - | BG5: - | BH5: 32.83 | BI5: 32.83 | BJ5: - | BK5: - | BL5: 32.8 | BM5: 32.8 | BN5: - | BO5: - | BP5: 32.8 | BQ5: 32.8 | BR5: - | BS5: - | BT5: 32.9536 | BU5: 32.9536 | BV5: - | BW5: - | BX5: - | BY5: 32.9536 | BZ5: 32.9536 | CA5: - | CB5: - | CC5: - | CD5: - | CE5: - | CF5: - | CG5: - | CH5: - | CI5: - | CJ5: - | CK5: - | CL5: - | CM5: - | CN5: - | CO5: - | CP5: - | CQ5: - | CR5: - | CS5: - | CT5: - | CU5: - | CV5: - | CW5: - | CX5: - | CY5: - | CZ5: - | DA5: - | DB5: -
